Workbook

Sheet How to Use
B2: 📘 Crack Every Test - CET 2027 Study Planner
B3: Your complete month-by-month roadmap to CET 99.99th%ile
B5: 📂 WHAT'S INSIDE
B6: 1. Monthly Study Plan | C6: Month-by-month topic roadmap, July 2026 → April 2027. Follow the sequence - it's ordered by priority, not textbook order.
B7: 2. Syllabus Tracker | C7: Every CET topic with Priority, Month Assigned, Questions to Solve, Done count, Progress bar and Status.
B8: 3. Progress Dashboard | C8: Auto-calculated completion % by section - updates live as you fill in Done counts.
B9: 📞 For Counselling: +91 7977041874 | 🔗 crackeverytest.com/popular-courses
B12: ✅ HOW TO USE THIS PLANNER
B13: Step 1 - Syllabus Tracker | C13: Open the Syllabus Tracker tab. Each time you finish questions on a topic, type the count in the 'Done ✏️' column. The progress bar and status update automatically.
B14: Step 2 - Monthly Plan | C14: Follow the Monthly Study Plan tab in sequence. Do not jump ahead - topics are ordered by dependency, not alphabetically.
B15: Step 3 - Dashboard Check-in | C15: Visit the Progress Dashboard every week. If any section is behind schedule, reallocate time before moving to the next month's topics.
B16: Step 4 - Priority Rules | C16: Compulsory topics (🟢) are non-negotiable for 99%ile. Optional topics (⚪) only if you have bandwidth after completing all compulsory ones.

Sheet Syllabus Tracker
A1: 📊 Syllabus Tracker - Fill in the 'Done ✏️' column as you complete questions
A2: 💡 Fill the yellow 'Done ✏️' cells only. Everything else updates automatically. Colors: 🔴 0% → 🟡 50% → 🟢 100%
A3: Section | B3: Topic | C3: Priority | D3: DEADLINE | E3: Target No of Qs | F3: Done ✏️ | G3: % Done | H3: Progress | I3: Status | J3: Notes
A4: Logical Reasoning | B4: Circular Puzzles | C4: 🟢 Compulsory | D4: 46327 | E4: 150 | F4: 0 | G4: =IF(E4=0,0,MIN(F4/E4,1)) -> 0 | H4: =G4 -> 0 | I4: =IF(G4=0,"⬜ Not Started",IF(G4<0.5,"🔄 In Progress",IF(G4<1,"🔥 Almost There","✅ Done!"))) -> ⬜ Not Started
B5: Tabular Puzzles | C5: 🟢 Compulsory | D5: 46327 | E5: 150 | F5: 0 | G5: =IF(E5=0,0,MIN(F5/E5,1)) -> 0 | H5: =G5 -> 0 | I5: =IF(G5=0,"⬜ Not Started",IF(G5<0.5,"🔄 In Progress",IF(G5<1,"🔥 Almost There","✅ Done!"))) -> ⬜ Not Started
B6: Linear Puzzles | C6: 🟢 Compulsory | D6: 46327 | E6: 120 | F6: 0 | G6: =IF(E6=0,0,MIN(F6/E6,1)) -> 0 | H6: =G6 -> 0 | I6: =IF(G6=0,"⬜ Not Started",IF(G6<0.5,"🔄 In Progress",IF(G6<1,"🔥 Almost There","✅ Done!"))) -> ⬜ Not Started
B7: Mixed Puzzles | C7: 🟢 Compulsory | D7: 46327 | E7: 120 | F7: 0 | G7: =IF(E7=0,0,MIN(F7/E7,1)) -> 0 | H7: =G7 -> 0 | I7: =IF(G7=0,"⬜ Not Started",IF(G7<0.5,"🔄 In Progress",IF(G7<1,"🔥 Almost There","✅ Done!"))) -> ⬜ Not Started
B8: Directions | C8: 🟢 Compulsory | D8: 46296 | E8: 60 | F8: 0 | G8: =IF(E8=0,0,MIN(F8/E8,1)) -> 0 | H8: =G8 -> 0 | I8: =IF(G8=0,"⬜ Not Started",IF(G8<0.5,"🔄 In Progress",IF(G8<1,"🔥 Almost There","✅ Done!"))) -> ⬜ Not Started
B9: Family Tree | C9: 🟢 Compulsory | D9: 46296 | E9: 80 | F9: 0 | G9: =IF(E9=0,0,MIN(F9/E9,1)) -> 0 | H9: =G9 -> 0 | I9: =IF(G9=0,"⬜ Not Started",IF(G9<0.5,"🔄 In Progress",IF(G9<1,"🔥 Almost There","✅ Done!"))) -> ⬜ Not Started
B10: Coding Decoding | C10: ⚪ Optional | D10: Jan 2027 | E10: 40 | F10: 0 | G10: =IF(E10=0,0,MIN(F10/E10,1)) -> 0 | H10: =G10 -> 0 | I10: =IF(G10=0,"⬜ Not Started",IF(G10<0.5,"🔄 In Progress",IF(G10<1,"🔥 Almost There","✅ Done!"))) -> ⬜ Not Started
B11: Coded Inequalities | C11: ⚪ Optional | D11: Jan 2027 | E11: 40 | F11: 0 | G11: =IF(E11=0,0,MIN(F11/E11,1)) -> 0 | H11: =G11 -> 0 | I11: =IF(G11=0,"⬜ Not Started",IF(G11<0.5,"🔄 In Progress",IF(G11<1,"🔥 Almost There","✅ Done!"))) -> ⬜ Not Started
B12: Syllogisms | C12: ⚪ Optional | D12: Jan 2027 | E12: 50 | F12: 0 | G12: =IF(E12=0,0,MIN(F12/E12,1)) -> 0 | H12: =G12 -> 0 | I12: =IF(G12=0,"⬜ Not Started",IF(G12<0.5,"🔄 In Progress",IF(G12<1,"🔥 Almost There","✅ Done!"))) -> ⬜ Not Started
B13: Alphanumeric Series | C13: 🟢 Compulsory | D13: Aug 2026 | E13: 60 | F13: 0 | G13: =IF(E13=0,0,MIN(F13/E13,1)) -> 0 | H13: =G13 -> 0 | I13: =IF(G13=0,"⬜ Not Started",IF(G13<0.5,"🔄 In Progress",IF(G13<1,"🔥 Almost There","✅ Done!"))) -> ⬜ Not Started
B14: Input Output | C14: 🟢 Compulsory | D14: Aug 2026 | E14: 60 | F14: 0 | G14: =IF(E14=0,0,MIN(F14/E14,1)) -> 0 | H14: =G14 -> 0 | I14: =IF(G14=0,"⬜ Not Started",IF(G14<0.5,"🔄 In Progress",IF(G14<1,"🔥 Almost There","✅ Done!"))) -> ⬜ Not Started
B15: Cause & Effect | C15: 🟢 Compulsory | D15: Dec 2026 | E15: 40 | F15: 0 | G15: =IF(E15=0,0,MIN(F15/E15,1)) -> 0 | H15: =G15 -> 0 | I15: =IF(G15=0,"⬜ Not Started",IF(G15<0.5,"🔄 In Progress",IF(G15<1,"🔥 Almost There","✅ Done!"))) -> ⬜ Not Started
B16: Course of Action | C16: 🟢 Compulsory | D16: Dec 2026 | E16: 40 | F16: 0 | G16: =IF(E16=0,0,MIN(F16/E16,1)) -> 0 | H16: =G16 -> 0 | I16: =IF(G16=0,"⬜ Not Started",IF(G16<0.5,"🔄 In Progress",IF(G16<1,"🔥 Almost There","✅ Done!"))) -> ⬜ Not Started
B17: Strong & Weak Arguments | C17: 🟢 Compulsory | D17: Dec 2026 | E17: 40 | F17: 0 | G17: =IF(E17=0,0,MIN(F17/E17,1)) -> 0 | H17: =G17 -> 0 | I17: =IF(G17=0,"⬜ Not Started",IF(G17<0.5,"🔄 In Progress",IF(G17<1,"🔥 Almost There","✅ Done!"))) -> ⬜ Not Started
B18: Inference | C18: 🟢 Compulsory | D18: Dec 2026 | E18: 50 | F18: 0 | G18: =IF(E18=0,0,MIN(F18/E18,1)) -> 0 | H18: =G18 -> 0 | I18: =IF(G18=0,"⬜ Not Started",IF(G18<0.5,"🔄 In Progress",IF(G18<1,"🔥 Almost There","✅ Done!"))) -> ⬜ Not Started
B19: Conclusion | C19: 🟢 Compulsory | D19: Dec 2026 | E19: 40 | F19: 0 | G19: =IF(E19=0,0,MIN(F19/E19,1)) -> 0 | H19: =G19 -> 0 | I19: =IF(G19=0,"⬜ Not Started",IF(G19<0.5,"🔄 In Progress",IF(G19<1,"🔥 Almost There","✅ Done!"))) -> ⬜ Not Started
B20: Assumptions | C20: 🟢 Compulsory | D20: Dec 2026 | E20: 50 | F20: 0 | G20: =IF(E20=0,0,MIN(F20/E20,1)) -> 0 | H20: =G20 -> 0 | I20: =IF(G20=0,"⬜ Not Started",IF(G20<0.5,"🔄 In Progress",IF(G20<1,"🔥 Almost There","✅ Done!"))) -> ⬜ Not Started
B21: Grouping | C21: 🟢 Compulsory | D21: Dec 2026 | E21: 60 | F21: 0 | G21: =IF(E21=0,0,MIN(F21/E21,1)) -> 0 | H21: =G21 -> 0 | I21: =IF(G21=0,"⬜ Not Started",IF(G21<0.5,"🔄 In Progress",IF(G21<1,"🔥 Almost There","✅ Done!"))) -> ⬜ Not Started
... B23: 4 Variable Venn Diagrams | C23: ⚪ Optional | D23: Jan 2027 | E23: 40 | F23: 0 | G23: =IF(E23=0,0,MIN(F23/E23,1)) -> 0 | H23: =G23 -> 0 | I23: =IF(G23=0,"⬜ Not Started",IF(G23<0.5,"🔄 In Progress",IF(G23<1,"🔥 Almost There","✅ Done!"))) -> ⬜ Not Started
A24: Quantitative Aptitude | B24: Percentages | C24: 🟢 Compulsory | D24: 46296 | E24: 100 | F24: 0 | G24: =IF(E24=0,0,MIN(F24/E24,1)) -> 0 | H24: =G24 -> 0 | I24: =IF(G24=0,"⬜ Not Started",IF(G24<0.5,"🔄 In Progress",IF(G24<1,"🔥 Almost There","✅ Done!"))) -> ⬜ Not Started
B25: Averages | C25: 🟢 Compulsory | D25: 46296 | E25: 80 | F25: 0 | G25: =IF(E25=0,0,MIN(F25/E25,1)) -> 0 | H25: =G25 -> 0 | I25: =IF(G25=0,"⬜ Not Started",IF(G25<0.5,"🔄 In Progress",IF(G25<1,"🔥 Almost There","✅ Done!"))) -> ⬜ Not Started
B26: Ratio & Proportion | C26: 🟢 Compulsory | D26: 46296 | E26: 100 | F26: 0 | G26: =IF(E26=0,0,MIN(F26/E26,1)) -> 0 | H26: =G26 -> 0 | I26: =IF(G26=0,"⬜ Not Started",IF(G26<0.5,"🔄 In Progress",IF(G26<1,"🔥 Almost There","✅ Done!"))) -> ⬜ Not Started
B27: Partnerships & Mixtures | C27: 🟢 Compulsory | D27: 46327 | E27: 80 | F27: 0 | G27: =IF(E27=0,0,MIN(F27/E27,1)) -> 0 | H27: =G27 -> 0 | I27: =IF(G27=0,"⬜ Not Started",IF(G27<0.5,"🔄 In Progress",IF(G27<1,"🔥 Almost There","✅ Done!"))) -> ⬜ Not Started
B28: Profit & Loss | C28: 🟢 Compulsory | D28: 46327 | E28: 100 | F28: 0 | G28: =IF(E28=0,0,MIN(F28/E28,1)) -> 0 | H28: =G28 -> 0 | I28: =IF(G28=0,"⬜ Not Started",IF(G28<0.5,"🔄 In Progress",IF(G28<1,"🔥 Almost There","✅ Done!"))) -> ⬜ Not Started
B29: Linear Equations | C29: 🟢 Compulsory | D29: Oct 2026 | E29: 80 | F29: 0 | G29: =IF(E29=0,0,MIN(F29/E29,1)) -> 0 | H29: =G29 -> 0 | I29: =IF(G29=0,"⬜ Not Started",IF(G29<0.5,"🔄 In Progress",IF(G29<1,"🔥 Almost There","✅ Done!"))) -> ⬜ Not Started
B30: LCM & HCF | C30: 🟢 Compulsory | D30: Oct 2026 | E30: 60 | F30: 0 | G30: =IF(E30=0,0,MIN(F30/E30,1)) -> 0 | H30: =G30 -> 0 | I30: =IF(G30=0,"⬜ Not Started",IF(G30<0.5,"🔄 In Progress",IF(G30<1,"🔥 Almost There","✅ Done!"))) -> ⬜ Not Started
B31: Time Speed Distance | C31: 🟢 Compulsory | D31: Oct 2026 | E31: 100 | F31: 0 | G31: =IF(E31=0,0,MIN(F31/E31,1)) -> 0 | H31: =G31 -> 0 | I31: =IF(G31=0,"⬜ Not Started",IF(G31<0.5,"🔄 In Progress",IF(G31<1,"🔥 Almost There","✅ Done!"))) -> ⬜ Not Started
B32: Time and Work | C32: 🟢 Compulsory | D32: Oct 2026 | E32: 80 | F32: 0 | G32: =IF(E32=0,0,MIN(F32/E32,1)) -> 0 | H32: =G32 -> 0 | I32: =IF(G32=0,"⬜ Not Started",IF(G32<0.5,"🔄 In Progress",IF(G32<1,"🔥 Almost There","✅ Done!"))) -> ⬜ Not Started
B33: SI & CI | C33: 🟢 Compulsory | D33: Oct 2026 | E33: 80 | F33: 0 | G33: =IF(E33=0,0,MIN(F33/E33,1)) -> 0 | H33: =G33 -> 0 | I33: =IF(G33=0,"⬜ Not Started",IF(G33<0.5,"🔄 In Progress",IF(G33<1,"🔥 Almost There","✅ Done!"))) -> ⬜ Not Started
B34: Geometry & Mensuration | C34: 🟢 Compulsory | D34: Nov 2026 | E34: 100 | F34: 0 | G34: =IF(E34=0,0,MIN(F34/E34,1)) -> 0 | H34: =G34 -> 0 | I34: =IF(G34=0,"⬜ Not Started",IF(G34<0.5,"🔄 In Progress",IF(G34<1,"🔥 Almost There","✅ Done!"))) -> ⬜ Not Started
B35: Algebra | C35: ⚪ Optional | D35: Jan 2027 | E35: 60 | F35: 0 | G35: =IF(E35=0,0,MIN(F35/E35,1)) -> 0 | H35: =G35 -> 0 | I35: =IF(G35=0,"⬜ Not Started",IF(G35<0.5,"🔄 In Progress",IF(G35<1,"🔥 Almost There","✅ Done!"))) -> ⬜ Not Started
B36: Number Series | C36: ⚪ Optional | D36: Jan 2027 | E36: 50 | F36: 0 | G36: =IF(E36=0,0,MIN(F36/E36,1)) -> 0 | H36: =G36 -> 0 | I36: =IF(G36=0,"⬜ Not Started",IF(G36<0.5,"🔄 In Progress",IF(G36<1,"🔥 Almost There","✅ Done!"))) -> ⬜ Not Started
B37: Problems on Ages | C37: 🟢 Compulsory | D37: Nov 2026 | E37: 50 | F37: 0 | G37: =IF(E37=0,0,MIN(F37/E37,1)) -> 0 | H37: =G37 -> 0 | I37: =IF(G37=0,"⬜ Not Started",IF(G37<0.5,"🔄 In Progress",IF(G37<1,"🔥 Almost There","✅ Done!"))) -> ⬜ Not Started
B38: Probability | C38: ⚪ Optional | D38: Jan 2027 | E38: 50 | F38: 0 | G38: =IF(E38=0,0,MIN(F38/E38,1)) -> 0 | H38: =G38 -> 0 | I38: =IF(G38=0,"⬜ Not Started",IF(G38<0.5,"🔄 In Progress",IF(G38<1,"🔥 Almost There","✅ Done!"))) -> ⬜ Not Started
B39: Number System | C39: 🟢 Compulsory | D39: Nov 2026 | E39: 80 | F39: 0 | G39: =IF(E39=0,0,MIN(F39/E39,1)) -> 0 | H39: =G39 -> 0 | I39: =IF(G39=0,"⬜ Not Started",IF(G39<0.5,"🔄 In Progress",IF(G39<1,"🔥 Almost There","✅ Done!"))) -> ⬜ Not Started
B40: Surds & Indices | C40: 🟢 Compulsory | D40: Aug 2026 | E40: 60 | F40: 0 | G40: =IF(E40=0,0,MIN(F40/E40,1)) -> 0 | H40: =G40 -> 0 | I40: =IF(G40=0,"⬜ Not Started",IF(G40<0.5,"🔄 In Progress",IF(G40<1,"🔥 Almost There","✅ Done!"))) -> ⬜ Not Started
... B49: GP & HP | C49: ⚪ Optional | D49: Jan 2027 | E49: 40 | F49: 0 | G49: =IF(E49=0,0,MIN(F49/E49,1)) -> 0 | H49: =G49 -> 0 | I49: =IF(G49=0,"⬜ Not Started",IF(G49<0.5,"🔄 In Progress",IF(G49<1,"🔥 Almost There","✅ Done!"))) -> ⬜ Not Started
...

Sheet Monthly Study Plan
A1: 📅 CET 2027 - Monthly Study Plan (July 2026 → April 2027)
A2: Month | B2: Phase | C2: Focus Topics | D2: Goal for the Month
A3: Jul 2026 | B3: Foundation (cont.) | C3: QA: Percentages, Averages, Ratio & Proportion LR: Directions, Family Tree Verbal: Grammar Basics DI: DI FIB | D3: Build the base - every other QA/DI topic leans on these.
A4: Aug 2026 | B4: Foundation (cont.) | C4: QA: Surds & Indices, Clocks & Calendars LR: Alphanumeric Series, Input Output Verbal: Sentence Correction | D4: Finish foundation tier before moving to full puzzle sets.
A5: Sep 2026 | B5: Core Build | C5: LR: Circular, Tabular, Linear & Mixed Puzzles (all 4 types) QA: Partnerships & Mixtures, Profit & Loss | D5: Puzzles carry the heaviest weightage - give this a full month.
A6: Oct 2026 | B6: Core Build (cont.) | C6: QA: Linear Equations, LCM & HCF, Time Speed Distance, Time & Work, SI & CI Abstract: Odd Man Out, Series, Paper Folding/Cutting | D6: Start Abstract in full - the entire section is compulsory.
A7: Nov 2026 | B7: Compulsory Wrap-up | C7: QA: Geometry & Mensuration, Problems on Ages, Number System, Quadratic Equations Abstract: Mirror & Water Images DI: Visuals, Tabular | D7: Close out every compulsory QA and Abstract topic.
A8: Dec 2026 | B8: Compulsory Wrap-up (cont.) | C8: LR: Cause & Effect, Course of Action, Inference, Conclusion, Assumptions, Grouping Verbal: Parajumbles, Sentence Completion, RC | D8: All compulsory topics across sections should be done by month-end.
A9: Jan 2027 | B9: Revision + Weak-Area Audit | C9: Re-attempt every compulsory topic once Optional topics if time allows: Coding-Decoding, Syllogisms, Number Series, Vocab+Cloze | D9: Flag weak zones. Start first sectional tests.
A10: Feb 2027 | B10: Mock-Intensive | C10: 2–3 full-length mocks per week Error-log review Slot-wise practice for normalization awareness | D10: No new topics. Mocks + error analysis only.
A11: Mar–Apr 2027 | B11: Final Revision | C11: Only revision • Timed sectionals • Formula & shortcut recall • Mental conditioning | D11: Zero new topics. Protect confidence and speed.

Sheet Progress Dashboard
A1: 📈 Progress Dashboard - Auto-updates from Syllabus Tracker
A2: Section | B2: Total Topics | C2: % Complete | D2: Progress | E2: Topics Done
A3: Logical Reasoning | B3: 20 | C3: =IFERROR(AVERAGE('Syllabus Tracker'!G4:G23),0) -> 0 | D3: =C3 -> 0 | E3: =COUNTIF('Syllabus Tracker'!G4:G23,1) -> 0
A4: Quantitative Aptitude | B4: 24 | C4: =IFERROR(AVERAGE('Syllabus Tracker'!G24:G47),0) -> 0 | D4: =C4 -> 0 | E4: =COUNTIF('Syllabus Tracker'!G24:G47,1) -> 0
A5: DI | B5: 3 | C5: =IFERROR(AVERAGE('Syllabus Tracker'!G48:G50),0) -> 0 | D5: =C5 -> 0 | E5: =COUNTIF('Syllabus Tracker'!G48:G50,1) -> 0
A6: Abstract | B6: 8 | C6: =IFERROR(AVERAGE('Syllabus Tracker'!G51:G58),0) -> 0 | D6: =C6 -> 0 | E6: =COUNTIF('Syllabus Tracker'!G51:G58,1) -> 0
A7: Verbal Ability & RC | B7: 10 | C7: =IFERROR(AVERAGE('Syllabus Tracker'!G59:G68),0) -> 0 | D7: =C7 -> 0 | E7: =COUNTIF('Syllabus Tracker'!G59:G68,1) -> 0
A8: 🎯 OVERALL | B8: 65 | C8: =IFERROR(AVERAGE('Syllabus Tracker'!G4:G70),0) -> 0 | D8: =C8 -> 0 | E8: =COUNTIF('Syllabus Tracker'!G4:G70,1) -> 0
